Loading python/3.7.3
  Loading requirement: tcl/8.6.8 gcc/8.3.0
Loading python/3.7.3
  Loading requirement: tcl/8.6.8 gcc/8.3.0
Traceback (most recent call last):
  File "train.py", line 117, in <module>
    for i, (x_data, y_data) in enumerate(train_dl):
  File "/afs/crc.nd.edu/user/c/cschaef6/.local/lib/python3.7/site-packages/torch/utils/data/dataloader.py", line 345, in __next__
    data = self._next_data()
  File "/afs/crc.nd.edu/user/c/cschaef6/.local/lib/python3.7/site-packages/torch/utils/data/dataloader.py", line 856, in _next_data
    return self._process_data(data)
  File "/afs/crc.nd.edu/user/c/cschaef6/.local/lib/python3.7/site-packages/torch/utils/data/dataloader.py", line 881, in _process_data
    data.reraise()
  File "/afs/crc.nd.edu/user/c/cschaef6/.local/lib/python3.7/site-packages/torch/_utils.py", line 395, in reraise
    raise self.exc_type(msg)
OSError: Caught OSError in DataLoader worker process 0.
Original Traceback (most recent call last):
  File "/afs/crc.nd.edu/user/c/cschaef6/.local/lib/python3.7/site-packages/torch/utils/data/_utils/worker.py", line 178, in _worker_loop
    data = fetcher.fetch(index)
  File "/afs/crc.nd.edu/user/c/cschaef6/.local/lib/python3.7/site-packages/torch/utils/data/_utils/fetch.py", line 44, in fetch
    data = [self.dataset[idx] for idx in possibly_batched_index]
  File "/afs/crc.nd.edu/user/c/cschaef6/.local/lib/python3.7/site-packages/torch/utils/data/_utils/fetch.py", line 44, in <listcomp>
    data = [self.dataset[idx] for idx in possibly_batched_index]
  File "/afs/crc.nd.edu/user/c/cschaef6/metal-snn/torchneuromorphic/torchneuromorphic/doublenmnist/doublenmnist_dataloaders.py", line 82, in __getitem__
    data_l, label_l =  self.data_train[key_l]
  File "/afs/crc.nd.edu/user/c/cschaef6/metal-snn/torchneuromorphic/torchneuromorphic/nmnist/nmnist_dataloaders.py", line 89, in __getitem__
    with h5py.File(self.root, 'r', swmr=True, libver="latest") as f:
  File "/opt/crc/p/python/3.7.3/gcc/lib/python3.7/site-packages/h5py/_hl/files.py", line 394, in __init__
    swmr=swmr)
  File "/opt/crc/p/python/3.7.3/gcc/lib/python3.7/site-packages/h5py/_hl/files.py", line 170, in make_fid
    fid = h5f.open(name, flags, fapl=fapl)
  File "h5py/_objects.pyx", line 54, in h5py._objects.with_phil.wrapper
  File "h5py/_objects.pyx", line 55, in h5py._objects.with_phil.wrapper
  File "h5py/h5f.pyx", line 85, in h5py.h5f.open
OSError: Unable to open file (unable to open file: name = 'data.nosync/nmnist/n_mnist.hdf5', errno = 2, error message = 'No such file or directory', flags = 40, o_flags = 0)

